if로 거르는거보다 try catch를 쓰는게 낫다  

예외는 십중팔구 데이터(업무), 배열  
```
try {

} catch {

} finally {

}

```
위를 보면 fianlly와 있고 없고는 차이가 없어보인다. 
그러나 차이는 try나 catch안에 `return`이 있으면 알수있다.

![image](https://user-images.githubusercontent.com/68311318/122237689-7bda9300-cefa-11eb-9085-8217cadd5060.png)
instanceof써서 처리하는게 더 좋다  
형제 관계 애를 조상 거쳐서 캐스팅하면 컴파일 에러는 안나는데 런타임 에러는 난다?  


## 예제
오버라이딩할때 부모가 throw하는거에서 더 추가할순없다(제어자랑 비슷)  
```java
package exam;

class NumberException extends Exception {}
class InvalidNumberException extends NumberException {}
class NotANumberException extends NumberException {}

class Base {
  void add(int a, int b)
      throws InvalidNumberException, NotANumberException {}
}
class Derived extends Base {
  //	@Override
  //	void add(int a, int b) throws InvalidNumberException, NotANumberException { //가능
  //		// TODO Auto-generated method stub
  //		//super.add(a, b);
  //	}
  //	@Override
  //	void add(int a, int b) throws InvalidNumberException { //가능
  //		// TODO Auto-generated method stub
  //		//super.add(a, b);
  //	}	
  //	@Override
  //	void add(int a, int b) throws NotANumberException { //가능
  //		// TODO Auto-generated method stub
  //		//super.add(a, b);
  //	}
  //	@Override
  //	void add(int a, int b) throws NumberException { //불가능
  //		// TODO Auto-generated method stub
  //		//super.add(a, b);
  //	}	
  //	@Override
  //	void add(int a, int b) throws Exception { //불가능
  //		// TODO Auto-generated method stub
  //		//super.add(a, b);
  //	}
}
public class ExceptionOverrideTest {

  public static void main(String[] args) {
    // TODO Auto-generated method stub

  }

}

```

## 예제
```java
package exam;

public class TryCatchFinallyExample {
	public static void main(String[] args) {
		String[] strArray = { "10", "2a" };
		int value = 0;
		for(int i=0; i<=2; i++) {
			try {
				value = Integer.parseInt(strArray[i]);
			} catch(ArrayIndexOutOfBoundsException e) {
				System.out.println("인덱스를 초과했음");
			} catch(NumberFormatException e) {
				System.out.println("숫자로 변환할 수 없음");
			} finally {
				System.out.println(value);
			}
		}
	}
}
```

## Exercise8
```java
package exam;

import java.util.InputMismatchException;
import java.util.Scanner;

public class Exercise8 {
	public static void main(String[] args) {
		// 1~100사이의 임의의 값을 얻어서 answer에 저장한다.
		int answer = (int) (Math.random() * 100) + 1;
		int input = 0; // 사용자입력을 저장할 공간
		int count = 0; // 시도횟수를 세기 위한 변수
		do {
			count++;
			System.out.print("1과 100사이의 값을 입력하세요 :");
			try {
				input = new Scanner(System.in).nextInt();
			} catch(InputMismatchException e) {
				System.out.println("유효하지 않은 값입니다. 다시 값을 입력해주세요.");
				continue;
			}
			if (answer > input) {
				System.out.println("더 큰 수를 입력하세요.");
			} else if (answer < input) {
				System.out.println("더 작은 수를 입력하세요.");
			} else {
				System.out.println("맞췄습니다.");
				System.out.println("시도횟수는 " + count + "번입니다.");
				break; // do-while문을 벗어난다
			}
		} while (true); // 무한반복문
	} // end of main
}

```

## Excercise9
```java
package exam;

class UnsupportedFuctionException extends RuntimeException {
	UnsupportedFuctionException(String message, int errCode) {
		super(message);
		ERR_CODE=errCode;
	}
	UnsupportedFuctionException(String message) {
		super(message);
		ERR_CODE=100;
	}
	final private int ERR_CODE;
	
	public int getErrorCode() {
		return ERR_CODE;
	}
	
	@Override
	public String getMessage() {
		return "["+ERR_CODE+"]"+super.getMessage();
	}
}

public class Exercise9 {
	public static void main(String[] args) {
		throw new UnsupportedFuctionException("지원하지 않는 기능입니다.",100);
	}

}
/*
Exception in thread "main" UnsupportedFuctionException: 
[100]지원하지 않는 기능입니다.
at Exercise9.main(Exercise9.java:26)
*/
```