# 1 예외처리(excetion handliing)
## 1.1 프로그램 오류
발생시점에 따라 컴파일에러(compile-time error)와 런타임 에러(runtime error)로 나눌 수 있다. 이외에도 논리적 에러(logical error)가 있는데, 컴파일도 잘되고 실행도 잘되지만 의도한 것과 다르게 동작하는 것을 말한다. 예를 들어, 창고의 재고가 음수가 된다던가, 게임프로그램에서 비행기가 총알에 맞아도 죽이 않는 경우가 이에 해당한다.  
소스코드를 컴파일하면 컴파일러가 소스코드(*.java)에 대해 오타나 잘못된 구문, 자료형 체크 등의 기본적인 검사를 수행하여 오류가 있는 지 알려준다. 컴파일러가 알려준 에러들을 모두 수정해서 컴파일을 성공적으로 마치고 나면, 클래스파일( *.class)이 생성되고, 생성된 클래스 파일을 실행할 수 있게 되는 것이다.  
컴파일러가 소스코드의 기본적인 사항은 컴파일 시에 모두 걸러줄 수 는 있겠지만, 실행도중에 발생할 수 있는 잠재적인 오류까지 검사할 수 없기 때문에 컴파일은 잘되었어도 실행 중에 에러에 의해서 잘못된 결과를 얻거나 프로그램이 비정상적으로 종료될 수 있다.  
런타임 에러를 방지하기 위해서는 프로그램의 실행도중 발생할 수 있는 모든 경우의 수를 고려하여 이에대한 대비를 하는 것이 필요하다. 자바에서는 실행시(runtime) 발생할 수 있는 프로그램 오류를 에러error와 예외exception 두가지로 분류하였다.  
에러는 메모리 부족(OutOfMemoryError)이나 스택오버플로우(StackOverflowError)와 같이 일단 발생하면 복구할 수 없는 심각한 오류이고, 예외는 발생하더라도 수습될 수 있는 비교적 덜 심각한 것이다.  
에러가 발생하면, 프로그램의 비정상적인 종료를 막을 길이 없지만, 예외는 발생하더라도 프로그래머가 이에 대한 적절한 코드를 미리 작성해 놓음으로써 프로그램의 비정상적인 종료를 막을 수 있다.  
```
에러 : 프로그램 코드에 의해서 수습될 수 없는 심각한 오류
예외 : 프로그램 코드에 의해서 수습될 수 있는 다소 미약한 오류
```

## 1.2 예외 클래스의 계층 구조
자바에서는 실행 시 발생할 수 있는 오류(Exception과 Error)를 클래스로 정의하였다. 역시 Object의 자손들이다.  
참고 : 그림은 전체 Exception 클래스 중에서 몇 개의 주요 클래스들만을 나열한 것이다.  
![image](https://user-images.githubusercontent.com/68311318/122022501-9c72f200-ce01-11eb-83d1-383ad75ca46c.png)  

모든 예외의 최고 조상은ㅇ Exception 클래스이다.  
![image](https://user-images.githubusercontent.com/68311318/122023148-3aff5300-ce02-11eb-862a-67b34fd1738a.png)  

그림에서 볼수잇듯이 예외클래스들은 다음과 같이 두그룹으로 나뉘어진다  
```
1 Exception클래스와 그 자손들(그림 8-2의 윗부분, RuntimeException과 자손들 제외)
2 RuntimeException클래스와 그 자손들(그림 8-2의 아랫부분)
```
앞으로 RuntimeException 클래스와 그 자손클래스들을 RuntimeException클래스들 이라하고, RuntimeException 클래스들을 제외한 나머지 클래스들을 Exception클래스들이라 하겠다.  

RuntimeException 클래스들은 주로 `프로그래머의 실수`에 의해서 발생될 수 있는 예외들로 자바의 프로그래밍 요소들과 관계가 깊다. 예를 들면, 배열의 범위를 벗어난다던가(ArrayIndexOutOfBoundsException), 값이 null인 참조변수의 멤버를 호출하려 했다던가(NullPointerException), 클래스간의 형변환을 잘못했다던가(ClassCastException), 정수를 0으로 나누려고(ArithmeticException)하는 경우에 발생한다.  

Exception클래스들은 주로 외부의 영향으로 발생할 수 있는 것들로서, `프로그램의 사용자`들의 동작에 의해서 발생하는 경우가 많다. 예를 들면, 존재하지 않는 파일의 이름을 입력했다던가(FileNotFoundException), 실수로 클래스의 이름을 잘못 적었다던가(FileNotFoundException), 실수로 클래스의 이름을 잘못 적었다던가(ClassNotFountException), 또는 입력한 데이터 형식이 잘못된(DataFormatException) 경우에 발생한다.  

```
Exception 클래스들 : 사용자의 실수와 같은 외적인 요인에 의해 발생하는 예외
RuntimeException 클래스들 : 프로그래머의 실수로 발생하는 예외
```

## 1.3 예외 처리하기 - try-catch문
예외처리의 목적은 예외의 발생으로 인한 실행 중인 프로그램의 갑작스런 비정상적 `종료`를 막고, 정상적인 실행상태를 유지할 수 있도록 하는 것이다  
```
예외처리의 
정의 - 프로그램 실행 시 발생할 수 있는 예외에 대비한 코드를 작성하는 것
목적 - 프로그램의 비정상 종료를 막고, 정상적인 실행상태를 유지하는 것
```
참고 : 에러와 예외는 모두 실행 시(runtime) 발생하는 오류이다.  

발생한 예외를 처리하지 못하면, 프로그램은 비정상적으로 종료되며, 처리되지 못한 예외(uncaught exception)의 원인을 화면에 출력한다.  

예외를 처리하기 위해서는 try-catch문을 사용한다
```java
try {
    // 예외가 발생할 가능성이 있는 문장들을 넣는다
} catch(Exception1 e) {
// Exception1이 발생했을 경우, 이를 처리하기 위한 문장을 넣는다
} catch(Exception2 e) {
// Exception2이 발생했을 경우, 이를 처리하기 위한 문장을 넣는다
} catch(Exception3 e) {
// Exception3이 발생했을 경우, 이를 처리하기 위한 문장을 넣는다
}
```
하나의 try블럭 다음에는 여러 종류의 예외를 처리할 수 잇도록 하나 이상의 catch블럭이 올수 있으며,이 중 발생한 예외의 종류와 일치하는 단 한 개의 catch블럭만 수행된다. 발생한 예외의 종류와 일치하는 catch블럭이 없으면 예외는 처리되지 않는다.  
참고 : if문과 달리 try블럭이나 catch블럭 내에 포함된 문장이 하나뿐이어도 괄호{}을 생략할 수 없다.  

```java
class Test {
  public static void main(String[] args) {
    try {
      try { } catch (Exception e) { }
    } catch (Exception e){
      try { } catch (Exception e) { } // 에러. 중복선언
    }

    try {

    } catch (Exception e) {

    }
  }
}
```
위의 예제는 아무일도 하지않는다. 단순히 예를 보여주기위한것.  

```java
class Test {
  public static void main(String[] args) {
    int number = 100;
    int result = 10;

    for(int i = 0; i < 10; i++) {
      result = number / (int) (Math.random() * 10);
      System.out.println(result);
    }

  }
}
```
실행결과
```
100
100
20
25
Exception in thread "main" java.lang.ArithmeticException: / by zero
	at Test.main(Test.java:7)

```
프로그램이 비정상적으로 종료된다. 정수는 0으로 나누는 것이 금지되어있기 때문에 발생했다. 하지만 실수를 0으로 나누는 것은 금지되어있지 않으며 예외가 발생하지 않는다.  
이제 예외처리를 해서, `예외가 발생하더라도` 프로그램이 비정상적으로 종료되지 않도록 수정해보자.  

```java
class Test {
  public static void main(String[] args) {
    int number = 100;
    int result = 10;

    for(int i = 0; i < 10; i++) {
      try {
        result = number / (int) (Math.random() * 10);
        System.out.println(result);
      } catch (ArithmeticException e) {
        System.out.println(0);
      }
    }

  }
}
```
실행결과
```
33
25
100
25
20
16
16
50
0
0

```
ArithmeticException이 발생하면 0이 출력되도록 했다. for문전체를 try 블록 안에 넣었다면 다른 결과가 나올것이다. 상황에 따라 try 블록의 범위를 지정하자.  

## 1.4 try-catch문에서의 흐름
try-catch문에서 예외가 발생한 경우와 발생하지 않았을때의 흐름(문장의 실행순서)이 달라진다.  
**try블럭 내에서 예외가 발생한 경우**  
1. 발생한 예외와 일치하는 catch블럭이 잇는지 확인한다.  
2. 일치하는 catch블럭을 찾게되면, 그 catch블럭 내의 문장들을 수행하고 전체 try-catch문을 빠져나가서 그 다음 문장을 계속 수행한다. 만일 일치하는 catch블럭을 찾지 못하면, 예외는 처리되지 못한다.  

**try블럭내에서 예외가 발생하지 않은 경우**  
1. catch블럭을 거치지않고 try-catch문을 빠져나가서 수행을 계속한다  

```java
class Test {
  public static void main(String[] args) {
    System.out.println(1);
    System.out.println(2);
    try {
      System.out.println(3);
      System.out.println(4);
    } catch (Exception e) {
      System.out.println(5);
    }
    System.out.println(6);
  }
}
```
```java
class Test {
  public static void main(String[] args) {
    System.out.println(1);
    System.out.println(2);
    try {
      System.out.println(3);
      System.out.println(0/0);
      System.out.println(4);
    } catch (ArithmeticException e) {
      System.out.println(5);
    }
    System.out.println(6);
  }
}
```
이처럼 try블럭에서 예외가 발생하면, 예외가 발생한 위치 이후에 있는 try블럭의 문장들은 수행되지 않으므로, try블럭에 포함시킬 코드의 범위를 잘 선택해야한다.  

## 1.5 예외의 발생과 catch블럭
예외가 발생하면, 발생한 예외에 해당하는 클래스의 인스턴스가 만들어진다.  
첫번째 catch블럭부터 차례로 내려가면서 catch블럭의 괄호()내에 선언된 참조변수의 종류와 생성된 예외클래스의 인스턴스에 `instanceof`연산자를 이용해서 검사하게 되는데, 검사결과가 true인 catch블럭을 만날때 까지 검사는 계속 된다.  
그래서 모든 예외 클래스는 Exception클래스의 자손이므로, ~.  

```java
class Test {
  public static void main(String[] args) {
    System.out.println(1);
    System.out.println(2);
    try {
      System.out.println(3);
      System.out.println(0/0);
      System.out.println(4);
    } catch (Exception e) {
      System.out.println(5);
    }
    System.out.println(6);

  }
}
```
instanceof연산결과가 true가 되어 ~.  

```java
class Test {
  public static void main(String[] args) {
    System.out.println(1);
    System.out.println(2);
    try {
      System.out.println(3);
      System.out.println(0/0);
      System.out.println(4);

    } catch (ArithmeticException ae) {
      if (ae instanceof ArithmeticException) {
        System.out.println("true");
      }
      System.out.println("Arithmetic Exception");
    } catch (Exception e) { // Arithmetic Exception을 제외한 모든 예외가 처리된다!
      System.out.println("Exception");
    }
    System.out.println(6);
  }
}
```

**printStackTrace()와 getMessage()**  
예외가 발생했을때 생성되는 예외클래스의 인스턴스에는 발생한 예외에 대한 정보가 담겨 잇으며, getMessage()와 printStackTrace()를 통해서 이 정보들을 얻을 수 있다.  
catch블럭의 괄호()에 선언된 참조변수를 통해 이 인스턴스에 접근할 수 있다. 이 참조변수는 선언된 catch블럭 내에서만 사용 가능하며, 자주 사용되는 메서드는 다음과 같다.  
```
printStackTrace() : 예외발생 당시의 호출스택(Call Stack)에 있었던 메서드의 정보와 예외메시지를 화면에 출력한다

getMessage() : 발생한 예외클래스의 인스턴스에 저장된 메시지를 얻을 수 있다
```
```java
class Test {
  public static void main(String[] args) {
    System.out.println(1);
    System.out.println(2);
    try {
      System.out.println(3);
      System.out.println(0/0);
      System.out.println(4);

    } catch (ArithmeticException ae) {
      ae.printStackTrace();
      System.out.println("예외메시지:" + ae.getMessage());
    }
    System.out.println(6);
  }
}
```
실행결과
```
1
2
3
java.lang.ArithmeticException: / by zero
	at Test.main(Test.java:7)
예외메시지:/ by zero
6
```
위 예제의 결과는 예외가 발생해서 비정상적으로 종료되었을 때의 결과와 비슷하지만 예외는 try-catch문에 의해 처리되었으며 프로그램은 `정상적으로 종료`되었다!  
그 대신 ArithmeticException인스턴스의 printStackTrace()를 사용해서, 호출 스택(call stack)에 대한 정보와 예외 메시지를 출력하였다. 이처럼 try-catch문으로 예외처리를 하여 예외가 발생해도 비정상적으로 종료하지 않도록 해주는 동시에, printStackTrace() 또는 getMessage()와 같은 메서드를 통해서 예외의 발생원인을 알 수 있다.  
참고 : printStackTrace(Printstream s) 또는 printStackTrace(PrintWriter s)를 사용하면 발생한 예외에 대한 정보를 파일에 저장할 수도 있다. 파일 입출력에 대한 내용은 15장에서 배운다  

**멀티 catch블럭**  
JDK1.7부터 `여러 catch블럭을` | 기호를 이용해서, `하나의 catch블럭으로` 합칠 수 있게 되었으며, 이를 멀티 catch블럭이라 한다. 아래의 코드에서 알 수 있듯이 멀티 catch블럭을 이용하면 중복된 코드를 줄일 수 있다. 그리고 | 기호로 연결할 수 있는 예외 클래스의 개수에는 제한이 없다.  
참고 : 멀티 catch 블럭에 사용되는 |는 논리연산자가 아닌 기호이다.  
```java
try {
    ...
} catch (ExceptionA e) {
    e.printStackTrace();
} catch (ExceptionB e2) {
   e2.printStackTrace();
}
```
=>
```java
try {
    ...
} catch (ExceptionA | ExceptionB e) {
    e.printStackTrace();
}
```
만일 멀티 catch블럭의 |기호로 연결된 예외 클래스가 조상과 자손의 관계에 잇다면 컴파일 에러가 발생한다.  
```java
try {
    ...
} catch (ParentException | ChildException e) { // 에러!
    e.printStackTrace();
}
```
왜냐하면, 두 예외 클래스가 조상과 자손 관계에 잇다면 그냥 조상 클래스만 써주는 것과 똑같기 때문이다. 불필요한 코드는 제거하라는 의미에서 에러가 발생하는 것이다.  
그리고 멀티 catch는 하나의 catch블럭으로 여러 예외를 처리하는 것이기 때문에, 발생한 예외를 멀티 catch블럭으로 처리하게 되었을때, 멀티 catch블럭 내에서는 실제로 어떤 예외가 발생한 것인지를 알 수 없다. 그래서 참조변수 e로 멀티 catch블럭에 | 기호로 연결된 예외 클래스들의 공통분모인 조상 예외 클래스에 선언된 멤버만 사용할 수 있다.  
```java
try {
    ...
} catch (ExceptionA | ExceptionB e){
    e.methodA(); // 에러. ExceptionA에 선언된 methodA()는 호출불가

    if(e instanceof ExceptionA) {
        ExceptionA e1 = (ExceptionA) e;
        e1.methodA(); // OK
    } else { // if(e instanceof ExceptionB)
        ...
    }

    e.printStackTrace();
}
```
필요하다면, 위와 같이 instanceof로 어떤 예외가 발생한 것인지를 확인하고 개별적으로 처리할 수는 있다. 그러나 이렇게 까지 해가면서 catch블럭을 합칠일은 거의 없을 것이다.  
마지막으로 멀티 catch블럭에 선언된 참조변수 e는 `상수`이므로 값을 변경할 수 없다는 제약이 있는데, 이것은 `여러 catch블럭이 하나의 참조변수를 공유하기 때문에 생기는 제약`으로 실제로 참조변수의 값을 바꿀일은 없을 것이다.  
여러 catch블럭을 멀티 catch블럭으로 합치는 경우는 대부분 코드를 간단히 하는 정도의 수준일 것이므로 이러한 제약에 대해 너무 고민하지 않기 바란다.  

## 1.6 예외 발생시키기
키워드 throw를 사용해서 프로그래머가 고의로 예외를 발생시킬 수 있으며, 방법은 아래의 순서를 따르면 된다
1. 먼저 연산자 new를 이용해서 발생시키려는 예외 클래스의 객체를 만든 다음  
Exception e = new Exception("고의로 발생시켰음");  
2. 키워드 throw를 이용해서 예외를 `발생`시킨다
throw e;  

```java
class Test {
  public static void main(String[] args) {
    try {
      Exception e = new Exception("고의로 발생시켰어");
      throw e; // 발생시킴
      // throw new Exception("고의로 발생시켰어");
    } catch (Exception e) {
      System.out.println("에러메시지:" + e.getMessage());
      e.printStackTrace();
    }
  }
}
```
Exception인스턴스를 생성할 때, 생성자에 String을 넣어 주면, 이 String이 Exception인스턴스에 메시지로 저장된다. 이 메시지는 e.getMessage()로 얻을 수 있다.  

```java
class Test {
  public static void main(String[] args) {
    throw new Exception(); // 고의로 발생시킨다
  }
}
```
컴파일 결과
```
Test.java:4: unreported exception java.lang.Exception; must be caught or declared to be thrown
    throw new Exception();
^
1 error
```
컴파일하면 위와같은 에러가 발생하여 컴파일이 완료되지 않을 것이다. 예외처리가 되어야할 부분에 예외처리가 되어있지 않다는 에러이다. 위의 결과에서 알수있는 것처럼, 앞서 그림에서 분류한 Exception클래스들(Exception클래스와 그 자손들)이 발생할 가능성이 있는 문장들에 대해 예외처리를 해주지 않으면 `컴파일조차` 되지않는다!  
```java
class Test {
  public static void main(String[] args) {
    throw new RuntimeException(); // 고의로 발생시킨다
  }
}
```
실행결과
```
Exception in thread "main" java.lang.RuntimeException
	at Test.main(Test.java:3)

```
이 예제는 예외처리를 하지 않았음에도 불구하고 이전의 예제와는 달리 성공적으로 컴파일될 것이다. 그러나 실행하면, 위의 실행결과처럼 RuntimeException이 발생하여 비정상적으로 종료될 것이다.  
이 예제가 명백히 RuntimeException을 발생시키는 코드를 가지고 있고, 이에 대한 예외처리를 하지 않았음에도 불구하고 성공적으로 컴파일되었다.  
이 장의 앞부분에서 설명한 것과 같이 RuntimeException클래스와 그 자손에 해당하는 예외는 프로그래머에 의해 실수로 발생하는 것들이기 때문에 예외처리를 강제하는 것이다. 만일 RuntimeException크래스들에 속하는 예외가 발생할 가능성이 있는 코드에도 예외처리를 필수로 해야한다면, `아래와 같이 참조 변수와 배열이 사용되는 모든 곳에 예외처리를 해주어야 할 것이다.`  
```java
try {
    int[] arr = new int[10];

    System.out.println(arr[0]);
} catch (ArrayIndexOutOfBoundsException ae) {
    ...
} catch (NullPoinerException ne) {
    ...
}
```
`컴파일러`가 예외처리를 확인하지 않는 RuntimeException클래스들은 unchecked예외라고 부르고 예외처리를 확인하는 Exception클래스들은 checked예외라고 부른다.  

## 1.7 메서드에 예외 선언하기
예외를 처리하는 방법에는 지금까지 배워온 try-catch문을 사용하는 것 외에, `예외를 메서드에 선언`하는 방법이 있다.  
메서드에 예외를 선언하려면, 메서드의 선언부에 키워드 throws를 사용해서 메서드 내에서 발생할 수 있는 예외를 적어주기만 하면 된다. 그리고 예외가 여러 개일 경우에는 쉼표(,)로 구분된다.  
```java
void method() throws Exception1, Exception2, ...ExceptionN {
    // 메서드의 내용
}
```
참고 : 예외를 발생시키는 키워드 throw와 예외를 메서드에 선언할 때 쓰이는 throw`s`를 잘 구별하자.  

만일 아래와 같이 모든 예외의 최고조상인 Exception클래스를 메서드에 선언하면, 이 메서드는 모든 종류의 예외가 발생할 가능성이 있다는 뜻이다.  
```java
void method() throws Exception {

}
```
이렇게 예외를 선언하면, 이 예외뿐만 아니라 그 자손타입의 예외까지도 `발생할수 있다는 점`에 주의하자. 앞서 `오버라이딩`에서 살펴본 것과 같이, 오버라이딩할 때는 `단순히 선언된 예외의 개수가 아니라 상속관계까지 고려`해야한다.  

메서드의 선언부에 예외를 선언함으로써 메서드를 사용하려는 사람이 메서드의 선언부를 보았을 때, 이 메서드를 사용하기 위해서는 어떠한 예외들이 처리되어져야 하는지 쉽게 알 수 있다.  
기존의 많은 언어들에서는 메서드에 예외선언을 하지 않기 때문에, 경험많은 프로그래머가 아니고서는 어떤 상황에 어떤 종류의 예외가 발생할 가능성이 잇는지 충분히 예측하기 힘들기 때문에 그에 대한 대비를 하는 것이 어려웟다.  
그러나 자바에서는 메서드를 작성할때 메서드 내에서 발생할 가능성이 있는 예외를 메서드의 선언부에 명ㅇ시하여 이 메서드를 `사용하는 쪽`에서는 이에 대한 처리를 하도록 강요하기 때문에, 프로그래머들의 짐을 덜어 주는 것은 물론이고 보다 견고한 프로그램 코드를 작성할 수 있도록 도와준다.  

![image](https://user-images.githubusercontent.com/68311318/122158601-ea423580-cea7-11eb-90dc-5e1498b5d055.png)  
그림은 Java API문서에서 찾아본 java.lang.Object클래스의 wait메서드에 대한 설명이다. 메서드의 선언부에 InterruptedException이 키워드 throws와 함께 적혀 있는 것을 볼 수 있다. 이것이 의미하는 바는 이 메서드에서 InterruptedException이 `발생할 수 있으니`, 이 메서드를 호출하고자 하는 메서드에서는 InterruptedException을 처리해주어야한다는 것이다.  
InterruptedException에 밑줄이 잇는 것으로 보아 링크가 걸려있음을 알 수 있을 것이다. 이 링크를 클릭하면, InterruptedException에 대한 설명을 볼 수 있다.  
![image](https://user-images.githubusercontent.com/68311318/122158617-f201da00-cea7-11eb-8985-e9bfbf3dfc8a.png)  
그림에서 볼수잇는 것 처럼, InterruptedException은 `Exception클래스의 자손`임을 알 수 있다. 따라서 InterrruptedException은 `반드시` 처리해주어야하는 예외임을 알 수 있다. 그래서 wait메서드의 선언부에 키워드 throws와 함께 선언되어져 잇는 것이다.  
Java API의 wait메서드 설명의 아래쪽에 있는 Throws: 를 보면, wait메서드에서 발생할 수 있는 예외의 리스트와 언제 발생하는 지에 대한 설명이 덧붙여져 있다.  
여기에는 두개의 예외가 적혀잇는데 메서드에 선언되어 있는 InterruptedException외에 또 하나의 예외(IllegalMonitorStateException)가 있다.
IllegalMonitorStateException역시 링크가 걸려있으므로 클릭하면  
![image](https://user-images.githubusercontent.com/68311318/122158640-f8905180-cea7-11eb-9f16-4d112199307c.png)  
나온다.  
그림에서 알수 잇듯이 IllegalMonitorStateException은 `RuntimeException클래스의 자손`이므로 IllegalMonitorStateException은 `예외처리를 해주지 않아도 된다.` 그래서 wait메서드의 선언부에 IllegalMonitorStatetException을 `적지 않은 것이다`!!  

지금까지 알아본 것처럼, 메서드에 예외를 `선언`할때 `일반적으로 RuntimeException클래스들은 적지 않는다`. 이 들을 메서드 선언부의 throws에 선언한다고 해서 문제가 되지는 않지만, 보통 반드시 처리해주어야하는 예외들만 선언한다.  

이처럼 Java API문서를 통해 사용하고자 하는 메서드의 `선언부`와 Throws:를 보고 이 메서드에서는 어떤 예외가 발생할 수 있으며 반드시 처리해주어야 하는 예외는 어떤 것들이 있는지 확인하는 것이 좋다.  

사실 예외를 메서드의 throws에 명시하는 성능 예외를 처리하는 것이 아니라, 자신(예외가 발생할 가능성이 있는 메서드)을 호출한 메서드에게 예외를 전달하여 예외처리를 떠맡기는 것이다.  
예외를 전달받은 메서드가 또다시 자신을 호출한 메서드에게 전달할 수 있으며, 이런 식으로 계속 호출스택에 있는 메서드들을 따라 전달되다가 제일 마지막에 잇는 main메서드에서도 예외가 처리되지 않으면, `main메서드마저` 종료되어 프로그램이 전체가 종료된다.  

```java
public class Test {
  public static void main(String[] args) throws Exception {
    method1();
  }

  private static void method1() throws Exception {
    method2();
  }

  private static void method2() throws Exception {
    throw new Exception();
  }
}
```
실행결과
```
Exception in thread "main" java.lang.Exception
	at Test.method2(Test.java:12)
	at Test.method1(Test.java:8)
	at Test.main(Test.java:4)

```
위 결과로부터 다음과 같은 사실을 알 수 있다  
1. 예외가 발생했을때 3개의 메서드 모두 호출스택에 있었으며  
2. 예외가 발생한 곳은 제일 윗줄에 있는 method2()라는 것과  
3. main메서드가 method1()을, 그리고 method1()은 method2()를 호출했다는 것을 알 수 있다  

위의 결과를 보면 예외가 발생한 메서드에서 예외처리를 하지 않고 자신을 호출한 메서드에게 예외를 넘겨줄 수 있지만, 이것으로 예외가 처리된 것은 아니고 예외를 단순히 전달만 하는 것이다. 결국 어느 한곳에서는 try-catch문으로 예외처리를 해주어야한다.  
```java
public class Test {
  public static void main(String[] args){
    method1();
  }

  private static void method1(){
    method2();
  }

  private static void method2(){
    throw new RuntimeException();
  }
}
```
실행결과
```
Exception in thread "main" java.lang.RuntimeException
	at Test.method2(Test.java:12)
	at Test.method1(Test.java:8)
	at Test.main(Test.java:4)

```
위의 결과도 마찬가지인데, 차이점은 예외처리를 안하거나(try-catch), 던지지 않아도(throws) 컴파일 에러가 안난다는 것이다!  

```java
public class Test {
  public static void main(String[] args) {
    method1();
  }

  private static void method1() {
    try {
      throw new Exception();
    } catch (Exception e) {
      System.out.println("method1에서 예외가 처리되었습니다");
      e.printStackTrace();
    }
  }
}
```
예외는 처리했지만, printStackTrace()를 통해 예외에 대한 정보를 화면에 출력하였다. 콘솔에 빨간글씨로 정보가 출력되어 마치 에러처럼 보인다.  

```java
public class Test {
  public static void main(String[] args) {
    try {
      method1();
    } catch (Exception e) {
      e.printStackTrace();
    }
  }

  private static void method1() throws Exception {
    throw new Exception();
  }
}
```
호출하는 쪽에서 예외를 처리했다. 그 전의 예제에서처럼 예외가 발생한 메서드 내에서 예외가 처리되면 호출한 메서드(main)에서는 예외가 발생했다는 사실조차 모른다.  

이처럼 예외는 예외가 발생한 메서드에서 처리할 수 도 있고, 호출한 메서드에서 처리할 수 도 있다. 또는 두 메서드가 처리를 분담할 수도 있다.  

```java
import java.io.File;

class Test {
  public static void main(String[] args) {
    //command line에서 입력받은 값을 이름으로 갖는 파일을 생성한다
    File f = createFile(args[0]);
    System.out.println(f.getName() + "파일이 생성되었습니다");
  }

  private static File createFile(String fileName) {
    try {
      if (fileName == null || fileName.equals("")) {
        throw new Exception("파일이름이 유효하지 않습니다");
      }
    } catch (Exception e) {
      fileName = "제목없음.txt";
    } finally {
      File f = new File(fileName);
      createNewFile(f);
      return f;
    }
  }

  private static void createNewFile(File f) {
    try {
      f.createNewFile();
    } catch (Exception e){

    }
  }
}
```
실행결과
```
"test.txt"
text.txt 파일이 성공적으로 생성되었습니다

""
제목없음.txt 파일이 성공적으로 생성되었습니다

dir *.txt
드라이브 C에 레이블이 없습니다
볼륨 일련번호 251C-08DD
디렉터리 C:\jdk1.8\work\ch8

제목없음 TXT 0 15-12-04 0:47 제목없음.txt
TEST TXT 0 15-12-04 0:47 제목없음.txt
```
참고 : 실행시 커맨드라인에 파일이름을 입력하지 않으면 args[0]이 유효하지않으므로 File f = createFile(args[0]);에서 ArrayIndexOutOfBoundsException이 발생한다  

이 예제는 예외가 발생한 메서드에서 직접 예외를 처리하도록 되어있다. createFile메서드를 호출한 main메서드에서는 예외가 발생한 사실을 알지 못한다. 적절하지 못한 파일이름(fileName)이 입력되면, 예외를 발생시키고, catch블럭에서, 파일이름을 '제목없음.txt'로 설정해서 파일을 생성한다. 그리고 finally블럭에서는 예외의 발생여부에 관계없이 파일을 생성하는 일을 한다.  

```java
import java.io.File;

class Test {
  public static void main(String[] args) {
    //command line에서 입력받은 값을 이름으로 갖는 파일을 생성한다
    File f = createFile(args[0]);
    System.out.println(f.getName() + "파일이 생성되었습니다");
  }

  private static File createFile(String fileName) {
    try {
      if (fileName == null || fileName.equals("")) {
        throw new Exception("파일이름이 유효하지 않습니다");
      }
    } catch (Exception e) {
      fileName = "제목없음.txt";
    } finally {
      File f = new File(fileName);
      createNewFile(f);
      return f;
    }
  }

  private static void createNewFile(File f) {
    try {
      f.createNewFile();
    } catch (Exception e){

    }
  }
}
```
참고 : File클래스의 createNewFile()은 `예외가 선언된` 메서드이므로 finally 블럭 내에 또다시 try-catch문으로 처리해야하므로 좀 복잡해진다. 이해를 돕기위해 예제의 기본흐름을 되도록 간단히 하려고 내부적으로 예외처리를 한 createNewFile(File f)메서드를 만들어서 사용했다.  

```java
import java.io.File;

class Test {
  public static void main(String[] args) {
    File f;
    try {
      f = createFile(args[0]);
      System.out.println(f.getName() + "파일이 성공적으로 생성되었습니다");
    } catch (Exception e) {
      System.out.println(e.getMessage() + "다시 입력해주시기 바랍니다");
    }
  }

  private static File createFile(String fileName) throws Exception {
    if(fileName == null || fileName.equals("")) {
      throw new Exception("파일이름이 유효하지않습니다");
    }

    File f = new File(fileName);

    f.createNewFile();
    return f;
  }
}
```
이 예제에서는 예외가 발생한 createFile메서드에서 잘못 입력된 파일이름을 임의로 처리하지 않고, 호출한 main메서드에게 예외가 발생했음을 `알려서` **파일이름을 다시 입력 받도록 하였다.**  

앞선 예제와는 달리 createFile메서드세 예외를 선언했기 때문에, File클래스의 create NewFile()에 대한 예외처리를 하지 않아도 되므로 createNewFile(File f)메서드를 굳이 따로 만들지 않았다.  

이처럼 예외가 발생한 멧드 내에서 자체적으로 처리해도 되는 것은 메서드 내에서 try-catch문을 사용해서 처리하고, 두번째 예제처럼 메서드에 호출 시 넘겨받아야할 값(fileName)을 `다시 받아야 하는경우`(메서드 내에서 자체적으로 해결이 안되는 경우!!!!)에는 예외를 메서드에 선언해서, 호출한 메서드에서 처리해야한다.  

## 1.8 finally 블럭
finally블럭은 예외의 발생여부와 상관없이 실행되어야 할 코드를 포함시킬 목적으로 사용된다. try-catch문의 끝에 선택적으로 덧붙여 사용할 수 있으며, try-catch-finally의 순서로 구성된다  
```java
try {
    // 예외가 발생할 가능성이 있는 문장들을 넣는다
} catch (Exception e) {
    // 예외처리를 위한 문장을 넣는다
} finally {
    // 예외의 발생여부에 관계없이 항상 수행되어야하는 문장을 넣는다
    // finally 블럭은 try-catch문의 맨 마지막에 위치해야한다
}
```
예외가 발생하면 try, catch, finally 순, 발생하지 않는 경우에는 try, finally 순으로 실행된다  
```java
class Test {
  public static void main(String[] args) {
    try {
      startInstall();
      copyFiles();
      deleteTempFiles();

    } catch (Exception e) {
      e.printStackTrace();
      deleteTempFiles();
    }
  }

  private static void deleteTempFiles() {}
  private static void copyFiles() {}
  private static void startInstall() {}
}
```
프로그램 설치과정 중에 예외가 발생하더라도, 설치에 사용된 임시파일들이 삭제되도록 catch블럭에 deleteTempFiles()를 넣었다.  
결국 try블럭의 문장을 수행하는 동안에(프로그램을 설치하는 과정에), 예외의 발생여부에 관계없이 deleteTempFiles()메서드는 실행되어야 하는 것이다.  

이럴때 finally블럭을 사용하면 좋다.  
```java
class Test {
  public static void main(String[] args) {
    try {
      startInstall();
      copyFiles();

    } catch (Exception e) {
      e.printStackTrace();
    } finally {
      deleteTempFiles();

    }
  }

  private static void deleteTempFiles() {}
  private static void copyFiles() {}
  private static void startInstall() {}
}
```

```java
class Test {
  public static void main(String[] args) {
    Test.method1();
    System.out.println("method1()의 수행을 마치고 main메서드로 돌아왔습니다");
  }

  private static void method1() {
    try {
      System.out.println("method1()이 호출되었습니다");
      return; // 현재 실행중인 메서드를 종료한다
    } catch (Exception e) {
      e.printStackTrace();
    } finally {
      System.out.println("method1()의 finally블럭이 실행되었습니다");
    }

  }
}
```
try블럭에서 return문이 실행되는 경우에도 finally블럭의 문장들이 먼저 실행된 후에, 현재 실행 중인 메서드를 종료한다.  
이와 마찬가지로 catch블럭의 문장 수행중에 return문을 만나도 finally블럭의 문장들은 수행된다.  

## 1.9 자동 자원 반환 try-with-resource문
## 1.10 사용자 정의 예외 만들기
보통 Exception 클래스 또는 RuntimeException클래스로부터 상속받아 클래스를 만들지만, 필요에 따라서 알맞은 예외 클래스를 선택할 수 도있다.  
참고 : 가능하면 새로운 예외 클래스를 만들기보다 기존의 예외클래스를 활용하자.  

```java
class MyException extends Exception {
    MyException(String msg) {
        super(msg);
    }
}
```
만들었다. 필요하다면 멤버변수나 메서드를 추가할 수 있다. Exception클래스는 생성시에 String값을 받아서 메시지로 저장할 수 있다. 우리가 만든 사용자 정의 예외 클래스도 메시지를 저장할 수 있을려면, 위에서 보는것과 같이 String을 매개변수로 받는 생성자를 추가해야한다.  

```java
class Test extends Exception {
  // 에러 코드값을 저장하기 위한 필드를 추가했다
  private final int ERR_CODE; // 생성자를 통해 초기화 하자

  public Test(String msg, int errCode) {
    super(msg);
    ERR_CODE = errCode;
  }

  public Test(String msg) {
    this(msg, 100);
  }

  public int getErrCode() {
    return ERR_CODE; // 이 메서드는 주로 getMessage()와 함께 사용될 것이다
  }
}
```
이전의 코드를 좀더 개선하여 메시지뿐만 아니라 에러코드 값도 저장할 수 있도록 ERR_CODE와 getErrCode()를 MyException클래스의 멤버로 추가했다.  
이렇게 함으로써 MyException이 발생했을때, catch블럭에서 getMessage()와 getErrCode()를 사용해서 에러코드와 메시지를 모두 얻을 수 있을 것이다.  

기존의 예외클래스는 주로 `Exception`을 상속받아서 **checked예외**로 작성하는 경우가 많았지만, 요즘은 예외처리를 `선택적으로` 할 수 잇도록 `RuntimeException`을 상속받아서 작성하는 쪽으로 바뀌어 가고 있다. checked예외는 반드시 예외처리를 해주어야 하기 때문에 예외처리가 불필요한 경우에도 try-catch문을 넣어서 코드가 복잡해지기 때문이다.  

예외처리를 강제하도록 한 이유는 프로그래밍경험이 적은 사람들도 보다 견고한 프로그램을 작성할 수 있게 유도하기 위한 것인데, 요즘은 자바가 탄생하던 20년전과 달리 프로그래밍 환경이 많이 달라졌다. 그 때 자바를 설계하던 사람들은 자바가 주로 소형 가전기기나, 데스크탑에서 실행될 것이라고 생각했지만 현재 자바는 모바일이나 웹프로그래밍에서 주로 쓰이고 잇다. 이처럼 프로그래밍 환경이 달라진 만큼 필수적으로 처리해야만 할 것 같았던 예외들이 선택적으로 처리해도 되는 상황으로 바뀌는 경우가 종종 발생하고 있다. 그래서 필요에 따라 예외처리의 여부를 선택할 수 있는 'unchecked예외'가 강제적인 checked예외보다 더 환영받고 있다.  

```java
class Test {
  public static void main(String[] args) {
    try {
      startInstall();
      copyFiles();

    } catch (SpaceException e) {
      System.out.println("에러 메시지 : " + e.getMessage());
      e.printStackTrace();
      System.out.println("공간을 확보한 후 다시 설치하시길 바랍니다");
    } catch (MemoryException e) {
      System.out.println("에러 메시지 : " + e.getMessage());
      e.printStackTrace();
      System.gc(); // Garbage Collector를 수행하여 메모리를 늘려준다
      System.out.println("다시 설치를 시도하세요");
    } finally {
      deleteTempFiles();
    }


  }
  private static void startInstall() throws SpaceException, MemoryException{
    if(!enoughSpace())
      throw new SpaceException("설치할 공간이 부족합니다");
    if(!enoughMemory())
      throw new MemoryException("메모리가 부족합니다");
  }

  private static void copyFiles() {}
  private static void deleteTempFiles() {}

  private static boolean enoughSpace() {
    return false;
  }

  private static boolean enoughMemory() {
    return true;
  }

}

class SpaceException extends Exception {
  public SpaceException(String msg) {
    super(msg);
  }
}

class MemoryException extends Exception {
  public MemoryException(String msg) {
    super(msg);
  }
}
```

## 1.11 예외 던지기(exception re-throwing)
한 메서드에서 발생할 수 있는 예외가 여럿인 경우, `몇개`는 try-catch문을 통해서 메서드 내에서 자체적으로 처리하고, 그 `나머지`는 선언부에 지정하여 호출한 메서드에서 처리하도록 함으로써, 양쪽에서 나눠서 처리하도록 할 수 있다.  
그리고 심지어는 `단 하나의 예외에 대해서도` 예외가 발생한 메서드와 호출한 메서드, 양쪽에서 처리하도록 할 수 있다!!!!  
이것은 `예외를 처리한 후에` **인위적으로 다시 발생**시키는 방법을 통해서 가능한데, 이것을 예외던지기(exception re-throwing)라고 한다.  
먼저 예외가 발생할 가능성이 있는 메서드에서 `try-catch`문을 사용해서 예외를 처리해주고 / `catch문`에서 필요한 작업을 행한 후에 `throw`문을 사용해서 예외를 다시 발생시킨다. 다시 발생한 예외는 이 메서드를 호출한 메서드에게 전달되고 호출한 메서드의 try-catch문에서 예외를 또다시 처리한다.  
이 방법은 하나의 예외에 대해서 예외가 발생한 메서드와 이를 호출한 메서드 `양쪽 모두에서 처리해줘야할 작업이 있을때` 사용된다.  
이때 주의할 점은 예외가 발생할 메서드에서는 try-catch문을 사용해서 예외처리를 해줌과 동시에 메서드의 선언부에 발생할 예외를 throws에 지정해줘야 한다는 것이다.(RuntimeException도?)  

```java
class Test {
  public static void main(String[] args) {
    try {
      method1();
    } catch (Exception e) {
      System.out.println("main메서드에서 예외가 처리되었습니다");
    }
  }

  private static void method1() throws Exception {
    try {
      throw new Exception();
    } catch (Exception e) {
      System.out.println("method1메서드에서 예외가 처리되었습니다");
      throw e;
    }
  }
}
```
결과에서 알 수 있듯이 method1()과 main메서드 `양쪽의 catch블럭`이 모두 수행되었음을 알 수 있다. method1()의 catch블럭애서 예외를 처리하고도 throw문을 통해 다시 예외를 발생시켰다. 그리고 이 예외를 main메서드 한 번더 처리하였다.  
`반환값이 있는 return문인 경우`, **catch블럭**에도 `return문`이 있어야한다. 예외가 발생했을 경우에도 값을 반환해야하기 때문이다.  

```java
static int method1() {
    try {
        System.out.println("method1()이 호출되었습니다");
        return 0;
    } catch (Exception e) {
        e.printStackTrace();
        return 1;
    } finally {
        System.out.println("method1()의 finally블럭이 실행되었습니다");
    }
}
```
또는 `catch블럭에서 예외 되던지기`를 해서 호출한 메서드로 `예외를 전달`하면, **return문이 없어도 된다.** 그래서 검증에서도 assert문대신 AssertError를 생성해서 던진다.  
참고 : assert문은 검증(assertion)을 수행하기 위한 문장으로 이 책에서는 다루지 않는다  

```java
static int method1() throws Exception {
    try {
        System.out.println("method1()이 호출되었습니다");
        return 0;
    } catch (Exception e) {
        e.printStackTrace();
        // return 1; // catch블럭내에도 return문이 필요하다.
        throw new Exception(); // return문 대신 예외를 호출한 메서드로 전달
    } finally {
        System.out.println("method1()의 finally블럭이 실행되었습니다");
    }
}
```
참고 : finally 블럭 내에도 return문을 사용할 수 있으며, try블럭이나 catch블럭의 return문 다음에 수행된다. 최종적으로 finally 블럭 내의 return문의 값이 반환된다.  

## 1.12 연결된 예외(chained exception)